<?xml version="1.0" ?>
<sdf version="1.9">
  <world name="drone_detection">

    <physics name="1ms" type="ignored">
      <max_step_size>0.001</max_step_size>
      <real_time_factor>1.0</real_time_factor>
    </physics>

    <plugin filename="gz-sim-physics-system" name="gz::sim::systems::Physics"/>
    <plugin filename="gz-sim-sensors-system" name="gz::sim::systems::Sensors">
      <render_engine>ogre2</render_engine>
    </plugin>
    <plugin filename="gz-sim-scene-broadcaster-system" name="gz::sim::systems::SceneBroadcaster"/>
    <plugin filename="gz-sim-user-commands-system" name="gz::sim::systems::UserCommands"/>

    <!-- Sky and atmosphere -->
    <scene>
      <ambient>0.4 0.4 0.4 1</ambient>
      <background>0.53 0.81 0.98 1</background>
      <sky>
        <time>10</time>
        <sunrise>6</sunrise>
        <sunset>20</sunset>
        <clouds>
          <speed>12</speed>
          <mean_size>0.5</mean_size>
          <ambient>0.8 0.8 0.8 1</ambient>
        </clouds>
      </sky>
      <shadows>true</shadows>
    </scene>

    <!-- Sun: bright directional light with shadows -->
    <light name="sun" type="directional">
      <cast_shadows>true</cast_shadows>
      <pose>0 0 100 0 0 0</pose>
      <diffuse>1.0 0.95 0.85 1</diffuse>
      <specular>0.3 0.3 0.3 1</specular>
      <direction>-0.3 0.1 -0.95</direction>
      <attenuation>
        <range>1000</range>
        <constant>0.9</constant>
        <linear>0.01</linear>
        <quadratic>0.001</quadratic>
      </attenuation>
    </light>

    <!-- Ambient fill light -->
    <light name="ambient_fill" type="directional">
      <cast_shadows>false</cast_shadows>
      <diffuse>0.3 0.35 0.4 1</diffuse>
      <specular>0.0 0.0 0.0 1</specular>
      <direction>0.3 -0.1 -0.5</direction>
    </light>

    <!-- Grass ground plane with PBR textures -->
    <model name="ground_plane">
      <static>true</static>
      <link name="link">
        <collision name="collision">
          <geometry><plane><normal>0 0 1</normal><size>500 500</size></plane></geometry>
        </collision>
        <visual name="visual">
          <geometry><plane><normal>0 0 1</normal><size>500 500</size></plane></geometry>
          <material>
            <ambient>0.5 0.6 0.4 1</ambient>
            <diffuse>0.5 0.6 0.4 1</diffuse>
            <specular>0.05 0.05 0.05 1</specular>
            <pbr>
              <metal>
                <albedo_map>model://drone_yolo_detection/materials/textures/grass_albedo.png</albedo_map>
                <normal_map>model://drone_yolo_detection/materials/textures/grass_normal.png</normal_map>
                <roughness_map>model://drone_yolo_detection/materials/textures/grass_roughness.png</roughness_map>
                <metalness>0.0</metalness>
              </metal>
            </pbr>
          </material>
          <plugin filename="gz-sim-ogre2-material-system" name="gz::sim::systems::Material">
            <texture_scale>40 40</texture_scale>
          </plugin>
        </visual>
      </link>
    </model>

    <!-- Detection targets -->
    <model name="box_red">
      <static>true</static>
      <pose>5 3 0.5 0 0 0</pose>
      <link name="link">
        <collision name="col"><geometry><box><size>1 1 1</size></box></geometry></collision>
        <visual name="vis">
          <geometry><box><size>1 1 1</size></box></geometry>
          <material><ambient>0.8 0.1 0.1 1</ambient><diffuse>0.8 0.1 0.1 1</diffuse></material>
        </visual>
      </link>
    </model>

    <model name="box_blue">
      <static>true</static>
      <pose>-4 5 0.5 0 0 0</pose>
      <link name="link">
        <collision name="col"><geometry><box><size>1.2 1.2 1</size></box></geometry></collision>
        <visual name="vis">
          <geometry><box><size>1.2 1.2 1</size></box></geometry>
          <material><ambient>0.1 0.1 0.8 1</ambient><diffuse>0.1 0.1 0.8 1</diffuse></material>
        </visual>
      </link>
    </model>

    <model name="cylinder_yellow">
      <static>true</static>
      <pose>2 -4 0.75 0 0 0</pose>
      <link name="link">
        <collision name="col"><geometry><cylinder><radius>0.5</radius><length>1.5</length></cylinder></geometry></collision>
        <visual name="vis">
          <geometry><cylinder><radius>0.5</radius><length>1.5</length></cylinder></geometry>
          <material><ambient>0.9 0.8 0.1 1</ambient><diffuse>0.9 0.8 0.1 1</diffuse></material>
        </visual>
      </link>
    </model>

    <!-- Iris quadrotor -->
    <model name="iris">
      <pose>0 0 0.195 0 0 0</pose>

      <link name="base_link">
        <inertial>
          <mass>1.5</mass>
          <inertia><ixx>0.029125</ixx><ixy>0</ixy><ixz>0</ixz><iyy>0.029125</iyy><iyz>0</iyz><izz>0.055225</izz></inertia>
        </inertial>
        <collision name="base_col">
          <geometry><box><size>0.47 0.47 0.11</size></box></geometry>
        </collision>
        <visual name="base_vis">
          <geometry><box><size>0.47 0.47 0.11</size></box></geometry>
          <material><ambient>0.1 0.1 0.1 1</ambient><diffuse>0.3 0.3 0.3 1</diffuse></material>
        </visual>

        <sensor name="camera_down" type="camera">
          <pose>0 0 -0.06 0 1.5708 0</pose>
          <always_on>true</always_on>
          <update_rate>30</update_rate>
          <camera>
            <horizontal_fov>1.3962634</horizontal_fov>
            <image><width>640</width><height>480</height><format>R8G8B8</format></image>
            <clip><near>0.1</near><far>100</far></clip>
          </camera>
          <topic>/drone/camera/image_raw</topic>
        </sensor>
      </link>

      <!-- Rotor 0: front-right, CCW -->
      <link name="rotor_0">
        <pose>0.13 -0.22 0.023 0 0 0</pose>
        <inertial><mass>0.025</mass><inertia><ixx>9.75e-7</ixx><ixy>0</ixy><ixz>0</ixz><iyy>1.66704e-4</iyy><iyz>0</iyz><izz>1.66704e-4</izz></inertia></inertial>
        <collision name="col"><pose>0 0 0 0 1.5707963 0</pose><geometry><cylinder><radius>0.128</radius><length>0.005</length></cylinder></geometry></collision>
        <visual name="vis"><pose>0 0 0 0 1.5707963 0</pose><geometry><cylinder><radius>0.128</radius><length>0.005</length></cylinder></geometry><material><ambient>0 0 0.8 1</ambient></material></visual>
      </link>
      <joint name="rotor_0_joint" type="revolute">
        <parent>base_link</parent><child>rotor_0</child>
        <axis><xyz>0 0 1</xyz><limit><lower>-1e16</lower><upper>1e16</upper></limit></axis>
      </joint>

      <!-- Rotor 1: back-left, CCW -->
      <link name="rotor_1">
        <pose>-0.13 0.22 0.023 0 0 0</pose>
        <inertial><mass>0.025</mass><inertia><ixx>9.75e-7</ixx><ixy>0</ixy><ixz>0</ixz><iyy>1.66704e-4</iyy><iyz>0</iyz><izz>1.66704e-4</izz></inertia></inertial>
        <collision name="col"><pose>0 0 0 0 1.5707963 0</pose><geometry><cylinder><radius>0.128</radius><length>0.005</length></cylinder></geometry></collision>
        <visual name="vis"><pose>0 0 0 0 1.5707963 0</pose><geometry><cylinder><radius>0.128</radius><length>0.005</length></cylinder></geometry><material><ambient>0 0 0.8 1</ambient></material></visual>
      </link>
      <joint name="rotor_1_joint" type="revolute">
        <parent>base_link</parent><child>rotor_1</child>
        <axis><xyz>0 0 1</xyz><limit><lower>-1e16</lower><upper>1e16</upper></limit></axis>
      </joint>

      <!-- Rotor 2: front-left, CW -->
      <link name="rotor_2">
        <pose>0.13 0.22 0.023 0 0 0</pose>
        <inertial><mass>0.025</mass><inertia><ixx>9.75e-7</ixx><ixy>0</ixy><ixz>0</ixz><iyy>1.66704e-4</iyy><iyz>0</iyz><izz>1.66704e-4</izz></inertia></inertial>
        <collision name="col"><pose>0 0 0 0 1.5707963 0</pose><geometry><cylinder><radius>0.128</radius><length>0.005</length></cylinder></geometry></collision>
        <visual name="vis"><pose>0 0 0 0 1.5707963 0</pose><geometry><cylinder><radius>0.128</radius><length>0.005</length></cylinder></geometry><material><ambient>0.8 0 0 1</ambient></material></visual>
      </link>
      <joint name="rotor_2_joint" type="revolute">
        <parent>base_link</parent><child>rotor_2</child>
        <axis><xyz>0 0 1</xyz><limit><lower>-1e16</lower><upper>1e16</upper></limit></axis>
      </joint>

      <!-- Rotor 3: back-right, CW -->
      <link name="rotor_3">
        <pose>-0.13 -0.22 0.023 0 0 0</pose>
        <inertial><mass>0.025</mass><inertia><ixx>9.75e-7</ixx><ixy>0</ixy><ixz>0</ixz><iyy>1.66704e-4</iyy><iyz>0</iyz><izz>1.66704e-4</izz></inertia></inertial>
        <collision name="col"><pose>0 0 0 0 1.5707963 0</pose><geometry><cylinder><radius>0.128</radius><length>0.005</length></cylinder></geometry></collision>
        <visual name="vis"><pose>0 0 0 0 1.5707963 0</pose><geometry><cylinder><radius>0.128</radius><length>0.005</length></cylinder></geometry><material><ambient>0.8 0 0 1</ambient></material></visual>
      </link>
      <joint name="rotor_3_joint" type="revolute">
        <parent>base_link</parent><child>rotor_3</child>
        <axis><xyz>0 0 1</xyz><limit><lower>-1e16</lower><upper>1e16</upper></limit></axis>
      </joint>

      <!-- Motor model plugins -->
      <plugin filename="gz-sim-multicopter-motor-model-system"
              name="gz::sim::systems::MulticopterMotorModel">
        <robotNamespace>iris</robotNamespace>
        <jointName>rotor_0_joint</jointName>
        <linkName>rotor_0</linkName>
        <turningDirection>ccw</turningDirection>
        <timeConstantUp>0.0125</timeConstantUp>
        <timeConstantDown>0.025</timeConstantDown>
        <maxRotVelocity>838</maxRotVelocity>
        <motorConstant>8.54858e-06</motorConstant>
        <momentConstant>0.016</momentConstant>
        <commandSubTopic>command/motor_speed</commandSubTopic>
        <motorNumber>0</motorNumber>
        <rotorDragCoefficient>8.06428e-05</rotorDragCoefficient>
        <rollingMomentCoefficient>1e-06</rollingMomentCoefficient>
        <motorSpeedPubTopic>motor_speed/0</motorSpeedPubTopic>
        <rotorVelocitySlowdownSim>10</rotorVelocitySlowdownSim>
      </plugin>

      <plugin filename="gz-sim-multicopter-motor-model-system"
              name="gz::sim::systems::MulticopterMotorModel">
        <robotNamespace>iris</robotNamespace>
        <jointName>rotor_1_joint</jointName>
        <linkName>rotor_1</linkName>
        <turningDirection>ccw</turningDirection>
        <timeConstantUp>0.0125</timeConstantUp>
        <timeConstantDown>0.025</timeConstantDown>
        <maxRotVelocity>838</maxRotVelocity>
        <motorConstant>8.54858e-06</motorConstant>
        <momentConstant>0.016</momentConstant>
        <commandSubTopic>command/motor_speed</commandSubTopic>
        <motorNumber>1</motorNumber>
        <rotorDragCoefficient>8.06428e-05</rotorDragCoefficient>
        <rollingMomentCoefficient>1e-06</rollingMomentCoefficient>
        <motorSpeedPubTopic>motor_speed/1</motorSpeedPubTopic>
        <rotorVelocitySlowdownSim>10</rotorVelocitySlowdownSim>
      </plugin>

      <plugin filename="gz-sim-multicopter-motor-model-system"
              name="gz::sim::systems::MulticopterMotorModel">
        <robotNamespace>iris</robotNamespace>
        <jointName>rotor_2_joint</jointName>
        <linkName>rotor_2</linkName>
        <turningDirection>cw</turningDirection>
        <timeConstantUp>0.0125</timeConstantUp>
        <timeConstantDown>0.025</timeConstantDown>
        <maxRotVelocity>838</maxRotVelocity>
        <motorConstant>8.54858e-06</motorConstant>
        <momentConstant>0.016</momentConstant>
        <commandSubTopic>command/motor_speed</commandSubTopic>
        <motorNumber>2</motorNumber>
        <rotorDragCoefficient>8.06428e-05</rotorDragCoefficient>
        <rollingMomentCoefficient>1e-06</rollingMomentCoefficient>
        <motorSpeedPubTopic>motor_speed/2</motorSpeedPubTopic>
        <rotorVelocitySlowdownSim>10</rotorVelocitySlowdownSim>
      </plugin>

      <plugin filename="gz-sim-multicopter-motor-model-system"
              name="gz::sim::systems::MulticopterMotorModel">
        <robotNamespace>iris</robotNamespace>
        <jointName>rotor_3_joint</jointName>
        <linkName>rotor_3</linkName>
        <turningDirection>cw</turningDirection>
        <timeConstantUp>0.0125</timeConstantUp>
        <timeConstantDown>0.025</timeConstantDown>
        <maxRotVelocity>838</maxRotVelocity>
        <motorConstant>8.54858e-06</motorConstant>
        <momentConstant>0.016</momentConstant>
        <commandSubTopic>command/motor_speed</commandSubTopic>
        <motorNumber>3</motorNumber>
        <rotorDragCoefficient>8.06428e-05</rotorDragCoefficient>
        <rollingMomentCoefficient>1e-06</rollingMomentCoefficient>
        <motorSpeedPubTopic>motor_speed/3</motorSpeedPubTopic>
        <rotorVelocitySlowdownSim>10</rotorVelocitySlowdownSim>
      </plugin>

      <!-- Velocity controller -->
      <plugin filename="gz-sim-multicopter-control-system"
              name="gz::sim::systems::MulticopterVelocityControl">
        <robotNamespace>iris</robotNamespace>
        <commandSubTopic>cmd_vel</commandSubTopic>
        <enableSubTopic>enable</enableSubTopic>
        <comLinkName>base_link</comLinkName>
        <velocityGain>2.7 2.7 2.7</velocityGain>
        <attitudeGain>2 3 0.15</attitudeGain>
        <angularRateGain>0.4 0.52 0.18</angularRateGain>
        <maximumLinearAcceleration>2 2 2</maximumLinearAcceleration>
        <rotorConfiguration>
          <rotor>
            <jointName>rotor_0_joint</jointName>
            <armLength>0.26</armLength>
            <forceConstant>8.54858e-06</forceConstant>
            <momentConstant>0.016</momentConstant>
            <direction>1</direction>
          </rotor>
          <rotor>
            <jointName>rotor_1_joint</jointName>
            <armLength>0.26</armLength>
            <forceConstant>8.54858e-06</forceConstant>
            <momentConstant>0.016</momentConstant>
            <direction>1</direction>
          </rotor>
          <rotor>
            <jointName>rotor_2_joint</jointName>
            <armLength>0.26</armLength>
            <forceConstant>8.54858e-06</forceConstant>
            <momentConstant>0.016</momentConstant>
            <direction>-1</direction>
          </rotor>
          <rotor>
            <jointName>rotor_3_joint</jointName>
            <armLength>0.26</armLength>
            <forceConstant>8.54858e-06</forceConstant>
            <momentConstant>0.016</momentConstant>
            <direction>-1</direction>
          </rotor>
        </rotorConfiguration>
      </plugin>

    </model>

  </world>
</sdf>
